[2024-05-08T13:59:48.728+0000] {local_task_job_runner.py:120} INFO - ::group::Pre task execution logs
[2024-05-08T13:59:48.794+0000] {taskinstance.py:2073} INFO - Dependencies all met for dep_context=non-requeueable deps ti=<TaskInstance: ETL1.ParallelSensorTasks.FetchSensor_d042ecc0-facd-11ed-a890-0242bed38519 manual__2024-05-08T13:53:21.462777+00:00 [queued]>
[2024-05-08T13:59:48.832+0000] {taskinstance.py:2073} INFO - Dependencies all met for dep_context=requeueable deps ti=<TaskInstance: ETL1.ParallelSensorTasks.FetchSensor_d042ecc0-facd-11ed-a890-0242bed38519 manual__2024-05-08T13:53:21.462777+00:00 [queued]>
[2024-05-08T13:59:48.841+0000] {taskinstance.py:2303} INFO - Starting attempt 2 of 4
[2024-05-08T13:59:48.912+0000] {taskinstance.py:2327} INFO - Executing <Task(PythonOperator): ParallelSensorTasks.FetchSensor_d042ecc0-facd-11ed-a890-0242bed38519> on 2024-05-08 13:53:21.462777+00:00
[2024-05-08T13:59:48.934+0000] {warnings.py:110} WARNING - /home/***/.local/lib/python3.12/site-packages/***/task/task_runner/standard_task_runner.py:61: DeprecationWarning: This process (pid=16366) is multi-threaded, use of fork() may lead to deadlocks in the child.
  pid = os.fork()

[2024-05-08T13:59:48.939+0000] {standard_task_runner.py:63} INFO - Started process 16388 to run task
[2024-05-08T13:59:48.947+0000] {standard_task_runner.py:90} INFO - Running: ['***', 'tasks', 'run', 'ETL1', 'ParallelSensorTasks.FetchSensor_d042ecc0-facd-11ed-a890-0242bed38519', 'manual__2024-05-08T13:53:21.462777+00:00', '--job-id', '10832', '--raw', '--subdir', 'DAGS_FOLDER/fetchDataFromMongo.py', '--cfg-path', '/tmp/tmpq34ssr0n']
[2024-05-08T13:59:48.952+0000] {standard_task_runner.py:91} INFO - Job 10832: Subtask ParallelSensorTasks.FetchSensor_d042ecc0-facd-11ed-a890-0242bed38519
[2024-05-08T13:59:49.045+0000] {task_command.py:426} INFO - Running <TaskInstance: ETL1.ParallelSensorTasks.FetchSensor_d042ecc0-facd-11ed-a890-0242bed38519 manual__2024-05-08T13:53:21.462777+00:00 [running]> on host 2c86a7408ff7
[2024-05-08T13:59:49.229+0000] {taskinstance.py:2644} INFO - Exporting env vars: AIRFLOW_CTX_DAG_OWNER='Shubham Bhatt' AIRFLOW_CTX_DAG_ID='ETL1' AIRFLOW_CTX_TASK_ID='ParallelSensorTasks.FetchSensor_d042ecc0-facd-11ed-a890-0242bed38519' AIRFLOW_CTX_EXECUTION_DATE='2024-05-08T13:53:21.462777+00:00' AIRFLOW_CTX_TRY_NUMBER='2' AIRFLOW_CTX_DAG_RUN_ID='manual__2024-05-08T13:53:21.462777+00:00'
[2024-05-08T13:59:49.232+0000] {taskinstance.py:430} INFO - ::endgroup::
[2024-05-08T13:59:58.298+0000] {logging_mixin.py:188} INFO - E11000 duplicate key error collection: pvvnl.transformed_data index: _id_ dup key: { _id: "004ea514-6c99-4a02-9025-debebcb59e96_2024-01-01 01:15:00" }, full error: {'index': 0, 'code': 11000, 'keyPattern': {'_id': 1}, 'keyValue': {'_id': '004ea514-6c99-4a02-9025-debebcb59e96_2024-01-01 01:15:00'}, 'errmsg': 'E11000 duplicate key error collection: pvvnl.transformed_data index: _id_ dup key: { _id: "004ea514-6c99-4a02-9025-debebcb59e96_2024-01-01 01:15:00" }'}
[2024-05-08T13:59:59.009+0000] {local_task_job_runner.py:310} WARNING - State of this instance has been externally set to None. Terminating instance.
[2024-05-08T13:59:59.011+0000] {local_task_job_runner.py:222} INFO - ::endgroup::
[2024-05-08T13:59:59.015+0000] {process_utils.py:132} INFO - Sending 15 to group 16388. PIDs of all processes in the group: [16388]
[2024-05-08T13:59:59.015+0000] {process_utils.py:87} INFO - Sending the signal 15 to group 16388
[2024-05-08T13:59:59.021+0000] {taskinstance.py:2607} ERROR - Received SIGTERM. Terminating subprocesses.
[2024-05-08T13:59:59.026+0000] {taskinstance.py:441} INFO - ::group::Post task execution logs
[2024-05-08T13:59:59.049+0000] {taskinstance.py:2890} ERROR - Task failed with exception
Traceback (most recent call last):
  File "/home/airflow/.local/lib/python3.12/site-packages/airflow/models/taskinstance.py", line 465, in _execute_task
    result = _execute_callable(context=context, **execute_callable_kwargs)
             ^^^^^^^^^^^^^^^^^^^^^^^^^^^^^^^^^^^^^^^^^^^^^^^^^^^^^^^^^^^^^
  File "/home/airflow/.local/lib/python3.12/site-packages/airflow/models/taskinstance.py", line 432, in _execute_callable
    return execute_callable(context=context, **execute_callable_kwargs)
           ^^^^^^^^^^^^^^^^^^^^^^^^^^^^^^^^^^^^^^^^^^^^^^^^^^^^^^^^^^^^
  File "/home/airflow/.local/lib/python3.12/site-packages/airflow/models/baseoperator.py", line 400, in wrapper
    return func(self, *args, **kwargs)
           ^^^^^^^^^^^^^^^^^^^^^^^^^^^
  File "/home/airflow/.local/lib/python3.12/site-packages/airflow/operators/python.py", line 235, in execute
    return_value = self.execute_callable()
                   ^^^^^^^^^^^^^^^^^^^^^^^
  File "/home/airflow/.local/lib/python3.12/site-packages/airflow/operators/python.py", line 252, in execute_callable
    return self.python_callable(*self.op_args, **self.op_kwargs)
           ^^^^^^^^^^^^^^^^^^^^^^^^^^^^^^^^^^^^^^^^^^^^^^^^^^^^^
  File "/opt/airflow/dags/fetchDataFromMongo.py", line 38, in fetch_and_transform_sensor_data
    thread.join()
  File "/usr/local/lib/python3.12/threading.py", line 1147, in join
    self._wait_for_tstate_lock()
  File "/usr/local/lib/python3.12/threading.py", line 1167, in _wait_for_tstate_lock
    if lock.acquire(block, timeout):
       ^^^^^^^^^^^^^^^^^^^^^^^^^^^^
  File "/home/airflow/.local/lib/python3.12/site-packages/airflow/models/taskinstance.py", line 2609, in signal_handler
    raise AirflowTaskTerminated("Task received SIGTERM signal")
airflow.exceptions.AirflowTaskTerminated: Task received SIGTERM signal
[2024-05-08T13:59:59.123+0000] {taskinstance.py:1205} INFO - Marking task as UP_FOR_RETRY. dag_id=ETL1, task_id=ParallelSensorTasks.FetchSensor_d042ecc0-facd-11ed-a890-0242bed38519, execution_date=20240508T135321, start_date=20240508T135948, end_date=20240508T135959
[2024-05-08T13:59:59.207+0000] {standard_task_runner.py:110} ERROR - Failed to execute job 10832 for task ParallelSensorTasks.FetchSensor_d042ecc0-facd-11ed-a890-0242bed38519 ((psycopg2.errors.ForeignKeyViolation) insert or update on table "task_fail" violates foreign key constraint "task_fail_ti_fkey"
DETAIL:  Key (dag_id, task_id, run_id, map_index)=(ETL1, ParallelSensorTasks.FetchSensor_d042ecc0-facd-11ed-a890-0242bed38519, manual__2024-05-08T13:53:21.462777+00:00, -1) is not present in table "task_instance".

[SQL: INSERT INTO task_fail (task_id, dag_id, run_id, map_index, start_date, end_date, duration) VALUES (%(task_id)s, %(dag_id)s, %(run_id)s, %(map_index)s, %(start_date)s, %(end_date)s, %(duration)s) RETURNING task_fail.id]
[parameters: {'task_id': 'ParallelSensorTasks.FetchSensor_d042ecc0-facd-11ed-a890-0242bed38519', 'dag_id': 'ETL1', 'run_id': 'manual__2024-05-08T13:53:21.462777+00:00', 'map_index': -1, 'start_date': datetime.datetime(2024, 5, 8, 13, 59, 48, 801678, tzinfo=Timezone('UTC')), 'end_date': datetime.datetime(2024, 5, 8, 13, 59, 59, 123324, tzinfo=Timezone('UTC')), 'duration': 10}]
(Background on this error at: https://sqlalche.me/e/14/gkpj); 16388)
[2024-05-08T13:59:59.269+0000] {process_utils.py:80} INFO - Process psutil.Process(pid=16388, status='terminated', exitcode=1, started='13:59:48') (16388) terminated with exit code 1
